Traceback (most recent call last):
  File "/opt/hostedtoolcache/Python/3.11.9/x64/lib/python3.11/site-packages/jupyter_cache/executors/utils.py", line 58, in single_nb_execution
    executenb(
  File "/opt/hostedtoolcache/Python/3.11.9/x64/lib/python3.11/site-packages/nbclient/client.py", line 1314, in execute
    return NotebookClient(nb=nb, resources=resources, km=km, **kwargs).execute()
           ^^^^^^^^^^^^^^^^^^^^^^^^^^^^^^^^^^^^^^^^^^^^^^^^^^^^^^^^^^^^^^^^^^^^^
  File "/opt/hostedtoolcache/Python/3.11.9/x64/lib/python3.11/site-packages/jupyter_core/utils/__init__.py", line 165, in wrapped
    return loop.run_until_complete(inner)
           ^^^^^^^^^^^^^^^^^^^^^^^^^^^^^^
  File "/opt/hostedtoolcache/Python/3.11.9/x64/lib/python3.11/asyncio/base_events.py", line 654, in run_until_complete
    return future.result()
           ^^^^^^^^^^^^^^^
  File "/opt/hostedtoolcache/Python/3.11.9/x64/lib/python3.11/site-packages/nbclient/client.py", line 709, in async_execute
    await self.async_execute_cell(
  File "/opt/hostedtoolcache/Python/3.11.9/x64/lib/python3.11/site-packages/nbclient/client.py", line 1062, in async_execute_cell
    await self._check_raise_for_error(cell, cell_index, exec_reply)
  File "/opt/hostedtoolcache/Python/3.11.9/x64/lib/python3.11/site-packages/nbclient/client.py", line 918, in _check_raise_for_error
    raise CellExecutionError.from_cell_and_msg(cell, exec_reply_content)
nbclient.exceptions.CellExecutionError: An error occurred while executing the following cell:
------------------
with new_trainer_context(config=config, args=args) as ctx:
    config = ctx.config
    task = ctx.task
    trainer = ctx.trainer
    task.setup(trainer)
    task.run()
------------------


[0;31m---------------------------------------------------------------------------[0m
[0;31mTypeError[0m                                 Traceback (most recent call last)
Cell [0;32mIn[9], line 1[0m
[0;32m----> 1[0m [38;5;28;01mwith[39;00m [43mnew_trainer_context[49m[43m([49m[43mconfig[49m[38;5;241;43m=[39;49m[43mconfig[49m[43m,[49m[43m [49m[43margs[49m[38;5;241;43m=[39;49m[43margs[49m[43m)[49m [38;5;28;01mas[39;00m ctx:
[1;32m      2[0m     config [38;5;241m=[39m ctx[38;5;241m.[39mconfig
[1;32m      3[0m     task [38;5;241m=[39m ctx[38;5;241m.[39mtask

File [0;32m/opt/hostedtoolcache/Python/3.11.9/x64/lib/python3.11/contextlib.py:301[0m, in [0;36mcontextmanager.<locals>.helper[0;34m(*args, **kwds)[0m
[1;32m    299[0m [38;5;129m@wraps[39m(func)
[1;32m    300[0m [38;5;28;01mdef[39;00m [38;5;21mhelper[39m([38;5;241m*[39margs, [38;5;241m*[39m[38;5;241m*[39mkwds):
[0;32m--> 301[0m     [38;5;28;01mreturn[39;00m [43m_GeneratorContextManager[49m[43m([49m[43mfunc[49m[43m,[49m[43m [49m[43margs[49m[43m,[49m[43m [49m[43mkwds[49m[43m)[49m

File [0;32m/opt/hostedtoolcache/Python/3.11.9/x64/lib/python3.11/contextlib.py:105[0m, in [0;36m_GeneratorContextManagerBase.__init__[0;34m(self, func, args, kwds)[0m
[1;32m    104[0m [38;5;28;01mdef[39;00m [38;5;21m__init__[39m([38;5;28mself[39m, func, args, kwds):
[0;32m--> 105[0m     [38;5;28mself[39m[38;5;241m.[39mgen [38;5;241m=[39m [43mfunc[49m[43m([49m[38;5;241;43m*[39;49m[43margs[49m[43m,[49m[43m [49m[38;5;241;43m*[39;49m[38;5;241;43m*[39;49m[43mkwds[49m[43m)[49m
[1;32m    106[0m     [38;5;28mself[39m[38;5;241m.[39mfunc, [38;5;28mself[39m[38;5;241m.[39margs, [38;5;28mself[39m[38;5;241m.[39mkwds [38;5;241m=[39m func, args, kwds
[1;32m    107[0m     [38;5;66;03m# Issue 19330: ensure context manager instances have good docstrings[39;00m

[0;31mTypeError[0m: new_trainer_context() got an unexpected keyword argument 'args'

